Workbook
Name Outline: 'Criteria Options'!$A$24:$E$24

Sheet Marking
B1: MMME3085: Robot Writing Software Project
B2: Student Name : | J2: I.D. Number : | O2: Marked By
A4: Developed Code -60%
B6: Code Compilation 3% | T6: =IF(C6="","No Selection","OK") -> No Selection | U6: =0.03*25*IF(C6='Criteria Options'!A5,0,IF(C6='Criteria Options'!B5,1,IF(C6='Criteria Options'!C5,2,IF(C6='Criteria Options'!D5,3,IF(C6='Criteria Options'!E5,4,0))))) -> 0
B7: Reading and storing font data 8% | T7: =IF(C7="","No Selection","OK") -> No Selection | U7: =0.08*25*IF(C7='Criteria Options'!A7,0,IF(C7='Criteria Options'!B7,1,IF(C7='Criteria Options'!C7,2,IF(C7='Criteria Options'!D7,3,IF(C7='Criteria Options'!E7,4,0))))) -> 0
B8: Input of font height and scaling of font data 5% | T8: =IF(C8="","No Selection","OK") -> No Selection | U8: =0.05*25*IF(C8='Criteria Options'!A9,0,IF(C8='Criteria Options'!B9,1,IF(C8='Criteria Options'!C9,2,IF(C8='Criteria Options'!D9,3,IF(C8='Criteria Options'!E9,4,0))))) -> 0
B9: Reading and processing text data 10% | T9: =IF(C9="","No Selection","OK") -> No Selection | U9: =0.1*25*IF(C9='Criteria Options'!A11,0,IF(C9='Criteria Options'!B11,1,IF(C9='Criteria Options'!C11,2,IF(C9='Criteria Options'!D11,3,IF(C9='Criteria Options'!E11,4,0))))) -> 0
B10: Positioning of letters drawn 10% | T10: =IF(C10="","No Selection","OK") -> No Selection | U10: =0.1*25*IF(C10='Criteria Options'!A13,0,IF(C10='Criteria Options'!B13,1,IF(C10='Criteria Options'!C13,2,IF(C10='Criteria Options'!D13,3,IF(C10='Criteria Options'!E13,4,0))))) -> 0
B11: Naming convention and variable type 5% | T11: =IF(C11="","No Selection","OK") -> No Selection | U11: =0.05*25*IF(C11='Criteria Options'!A15,0,IF(C11='Criteria Options'!B15,1,IF(C11='Criteria Options'!C15,2,IF(C11='Criteria Options'!D15,3,IF(C11='Criteria Options'!E15,4,0))))) -> 0
B12: Best Practice/Quality of Code - code structure 8% | T12: =IF(C12="","No Selection","OK") -> No Selection | U12: =0.08*25*IF(C12='Criteria Options'!A17,0,IF(C12='Criteria Options'!B17,1,IF(C12='Criteria Options'!C17,2,IF(C12='Criteria Options'!D17,3,IF(C12='Criteria Options'!E17,4,0))))) -> 0
B13: Best Practice/Quality of Code - error checking and use of return codes 7% | T13: =IF(C13="","No Selection","OK") -> No Selection | U13: =0.07*25*IF(C13='Criteria Options'!A19,0,IF(C13='Criteria Options'!B19,1,IF(C13='Criteria Options'!C19,2,IF(C13='Criteria Options'!D19,3,IF(C13='Criteria Options'!E19,4,0))))) -> 0
B14: Commenting and code layout 4% | T14: =IF(C14="","No Selection","OK") -> No Selection | U14: =0.04*25*IF(C14='Criteria Options'!A21,0,IF(C14='Criteria Options'!B21,1,IF(C14='Criteria Options'!C21,2,IF(C14='Criteria Options'!D21,3,IF(C14='Criteria Options'!E21,4,0))))) -> 0
A16: System Manual - 20%
B18: Outline of the overall function of the program 4% | T18: =IF(C18="","No Selection","OK") -> No Selection | U18: =0.04*25*IF(C18='Criteria Options'!A24,0,IF(C18='Criteria Options'!B24,1,IF(C18='Criteria Options'!C24,2,IF(C18='Criteria Options'!D24,3,IF(C18='Criteria Options'!E24,4,0))))) -> 0
B19: Details of files used in the project (.c/.h) with indications of where configuration changes may be needed during development 4% | T19: =IF(C19="","No Selection","OK") -> No Selection | U19: =0.04*25*IF(C19='Criteria Options'!A26,0,IF(C19='Criteria Options'!B26,1,IF(C19='Criteria Options'!C26,2,IF(C19='Criteria Options'!D26,3,IF(C19='Criteria Options'!E26,4,0))))) -> 0
B20: Data storage for key items 4% | T20: =IF(C20="","No Selection","OK") -> No Selection | U20: =0.04*25*IF(C20='Criteria Options'!A28,0,IF(C20='Criteria Options'!B28,1,IF(C20='Criteria Options'!C28,2,IF(C20='Criteria Options'!D28,3,IF(C20='Criteria Options'!E28,4,0))))) -> 0
B21: Key functions (you need only list those you will develop, those provided e.g. RS232 need not be detailed) 4% | T21: =IF(C21="","No Selection","OK") -> No Selection | U21: =0.04*25*IF(C21='Criteria Options'!A30,0,IF(C21='Criteria Options'!B30,1,IF(C21='Criteria Options'!C30,2,IF(C21='Criteria Options'!D30,3,IF(C21='Criteria Options'!E30,4,0))))) -> 0
B22: Testing data for functions and overall application 4% | T22: =IF(C22="","No Selection","OK") -> No Selection | U22: =0.04*25*IF(C22='Criteria Options'!A32,0,IF(C22='Criteria Options'!B32,1,IF(C22='Criteria Options'!C32,2,IF(C22='Criteria Options'!D32,3,IF(C22='Criteria Options'!E32,4,0))))) -> 0
A24: Flowchart - 10%
B26: Flowchart detailing the required operation of the code 7% | T26: =IF(C26="","No Selection","OK") -> No Selection | U26: =0.07*25*IF(C26='Criteria Options'!A35,0,IF(C26='Criteria Options'!B35,1,IF(C26='Criteria Options'!C35,2,IF(C26='Criteria Options'!D35,3,IF(C26='Criteria Options'!E35,4,0))))) -> 0
B27: Quality of work (ease of following, layout, consistency in fonts etc.) as distinct from the logical flow of the code 3% | T27: =IF(C27="","No Selection","OK") -> No Selection | U27: =0.03*25*IF(C27='Criteria Options'!A37,0,IF(C27='Criteria Options'!B37,1,IF(C27='Criteria Options'!C37,2,IF(C27='Criteria Options'!D37,3,IF(C27='Criteria Options'!E37,4,0))))) -> 0
A29: Use of version control - 5%
B31: Setup of git repository and its use to store changes to documents 5% | T31: =IF(C31="","No Selection","OK") -> No Selection | U31: =0.05*25*IF(C31='Criteria Options'!A40,0,IF(C31='Criteria Options'!B40,1,IF(C31='Criteria Options'!C40,2,IF(C31='Criteria Options'!D40,3,IF(C31='Criteria Options'!E40,4,0))))) -> 0
A33: Robot Testing - 5%
B35: Testing of code with drawing robot in lab session 5% | T35: =IF(C35="","No Selection","OK") -> No Selection | U35: =0.05*25*IF(C35='Criteria Options'!A44,0,IF(C35='Criteria Options'!B44,1,IF(C35='Criteria Options'!C44,2,IF(C35='Criteria Options'!D44,3,IF(C35='Criteria Options'!E44,4,0))))) -> 0
A38: General Comments
B40: General Comments:

Sheet Criteria Options
A1: 0 | B1: 0.25 | C1: 0.5 | D1: 0.75 | E1: 1
A2: No answer | B2: Poor answer | C2: Adequate answer | D2: Good answer | E2: Excellent answer
A3: Developed Code - 60%
A4: Code compilation - 3%
A5: No code is provided | B5: Code does not compile | C5: Code compiles but there are warnings OR it does not give valid output | D5: Code compiles and gives valid output but there are warnings | E5: Code compiles without warnings and gives valid output
A6: Reading and storing font data - 8%
A7: No font data is read from file | B7: Some data is read from the file but is not stored | C7: Some data is read from the file and stored OR all data is read from the file but is not stored | D7: All data is read from the file and stored but the data format is not optimal | E7: All font data is read from the file and stored into a suitable data format
A8: Input of font height and scaling of font data - 5%
A9: No user input for font height | B9: A height is input by the user but there is no range checking AND it is not used to scale the font data | C9: A height is input by the user: there is no range checking or it is not used to scale the font data OR height is hard coded but scaling is correct for that height | D9: A height is input by the user with range checking but the scaling is incorrect | E9: A height is input by the user with range checking and is used to correctly scale the font data
A10: Reading and processing text data - 10%
A11: No text data is read from file | B11: Some text is read from the file but is not used | C11: Some text is read from the file and the corresponding font data located but this is not used to generate any output data | D11: All text is read from the file and the corresponding font data located. Output data is sent to the robot but this is either the whole text at once or one letter at a time. | E11: All text data is read from the file, processing each word and sending to the robot before the next text data is read
A12: Positioning of letters drawn - 10%
A13: No letters are drawn | B13: Some letters are drawn but the position and orientation are incorrect | C13: Some letters are drawn in the correct position and orientation but the line ends and new lines are not correctly processed | D13: Most letters are drawn correctly, in the correct position and orientation. New lines are processed correctly. Words are split across lines OR the line width is incorrect | E13: All letters are drawn correctly, in the correct position and orientation. New lines are processed correctly. Words are complete (ie a new line is forced if the word would exceed the allowable line width). The correct width of lines is used
A14: Naming convention and variable type - 5%
A15: No code is provided | B15: Naming of variables/functions is such that purpose cannot be determined from them. | C15: An attempt to use appropriate names for functions/variables has been made however in many places the choice is likely to lead to confusion AND variables are unsuited to the item they are holding. | D15: An attempt to use appropriate names for functions/variables has been made howver in many places the choice is likely to lead to confusion OR variable types are unsuited to the item they are holding. | E15: A clear and sensible approach to naming of functions and variables has been adopted throughout the code. Variable types are also appropriate to the items being stored.
A16: Best Practice/Quality of Code - code structure - 8%
A17: Code is of such poor quality/structure that its operation cannot be determined without extensive study (e.g. all user developed code is within a single main() function). | B17: The flow of the code (within functions including main() ) is such that the operation is not immediately clear leading to confusion over its operation. Little use of functions is made meaning code cannot be easily studied nor debugged. | C17: Some use has been made of functions, although there are still parts of the code where better use of functions would have clarified its operation. | D17: Code has been split into functions each of which has a clear flow however it is not always possible to check if their operation has been successful. | E17: Code has been split into functions each of which has a clear flow with appropriate return values allowing correct operation to be validated.
A18: Best Practice/Quality of Code - error checking and use of return codes - 7%
A19: No error checking has been used in the code | B19: There is very limited error checking in the code. | C19: Full error checking has not been applied to user input and interaction with the operating system (e.g. testing successful opening of files) AND functions are not returning error codes (where appropriate). | D19: Full error checking has not been applied to user input and interaction with the operating system (e.g. testing successful opening of files) OR functions are not returning error codes (where appropriate). | E19: Suitable error checking has been applied throughout (with exit codes from functions to indicate success/failure).
A20: Commenting and code layout - 4%
A21: None provided. | B21: Limited commenting has been used meaning that to understand complex sections of code would require considerable reading of the code AND layout of code makes it difficult to follow. | C21: Limited commenting has been used meaning that to understand complex sections of code would require considerable reading of the code OR layout of code makes it difficult to follow. | D21: The code is commented reasonably well and the code layout makes it relatively easy to follow. | E21: Comments meet requirements of good coding practice and code layout makes it easy to follow.
A22: System manual - 20%
A23: Outline of the overall function of the program - 4%
A24: Not provided | B24: Outline is of such limited detail as not to provide even the basic information on the functioning of the software. | C24: Only a limited outline of the system has been provided. Considerable investigation would be needed to obtain a full understanding of how the software works. | D24: The analysis of the system has provided the majority of the details required, however some further work would be needed to clarify specific details before a full understanding could be gained. | E24: The analysis of the system is of sufficient detail that a full understanding of the operational flow and data requirements of the software can be gained.
A25: Details of files used in the project - 4%
A26: None provided. | B26: List of files in the project is given however no further information is provided | C26: List of files in the project is given. An indication of functionality each provides is provided OR any parameters to be set (e.g. COM port) are specified OR details of where conditional compilation is used to determine mode of operation | D26: Full details of the files and functionality is provided. Any parameters to be set (e.g. COM port) are specified OR details of where conditional compilation is used to determine mode of operation | E26: Full details of the files and functionality is provided. Any parameters to be set (e.g. COM port) are specified AND details of where conditional compilation is used to determine mode of operation
A27: Data storage for KEY items -4%
A28: None provided. | B28: Limited items are indicated although the exact nature of how key elements are stored is not explicitly specified. | C28: Some data storage is specified but the detail of how key elements are stored and the rationale behind the choice of data type(s) is unclear or incorrect. | D28: Data storage is detailed, how key elements are stored is provided, however the rationale behind the choice of data type(s) is not clear. | E28: All relevant information on data storage for key items is provided.
A29: KEY functions as developed for the application - 4%
A30: No functions used. | B30: A list of functions for the code is provided, however no input/return parameters are provided AND function names are NOT descriptive of the operation of the function. | C30: A list of functions for the code is provided. Input/return parameters are incomplete OR function names are NOT descriptive of the operation of the function. | D30: A list of all key functions for the code is provided. Input/return parameters are incomplete. Function names are descriptive of the operation of the function. Some operation details are provided. | E30: A clear list of the key functions in the code has been provided. Function names are applicable to the task and input/return parameters are fully specified. Operation details are provided.
A31: Testing information -4%
A32: No testing information has been provided. | B32: Test data is provided, however it is insufficient to allow testing of all program paths (e.g. test case data is only provided for the 'OK' case). Test data for some functions or main is missing. | C32: Testing data is provided for all functions OR the main program. Only limited examples are provided and coverage is incomplete. | D32: Testing data follows the flow of the code, providing data for all functions and the main program, however test coverage is incomplete. | E32: Comprehensive testing data is provided that verifies the correct operational flow of the application.
A33: Flowchart
A34: Flowchart, operation of code
A35: No flowchart(s) indicating the code flow have been provided. | B35: A flowchart(s) has been provided but it provides only the most basic information - it would not be possible to develop/understand the code based on these. | C35: More detailed flowchart(s) have been provided however, in places, they do not show how the full implementation is done (e.g. no indication of function calls) and/or indicators of flow (e.g. yes/no indicators in decisions) are missing. | D35: More detailed flowchart(s) have been provided, including flowcharts for functions. In places, however, they do not show how the full implementation is done (e.g. no suitable paths for error trapping). | E35: Flowcharts are comprehensive showing the flow of code. They include flowcharts for functions, suitable paths for error trapping and all required items for development/understanding of correctly operating code.
A36: Flowchart, quality of work, layout etc
A37: No flowchart(s) have been provided. | B37: Flowchart is difficult to follow which is likely to cause errors in developed code (e.g. wrong decisions, lines merging or crossing etc. ). | C37: The flowchart is generally well laid out, some ambiguity AND errors in flow logic remain. | D37: The flowchart is generally well laid out, some ambiguity OR errors in flow logic remain. | E37: Flowchart is sufficiently well laid out that the code can be easily developed/understood.
A38: Use of version control - 5%
A39: Testing of code with drawing robot
A40: No version control has been used or the git repository does not contain any documents. | B40: A git repository has been submitted but some of the code and documentation files are missing. | C40: A git repository has been set up containing all of the project, code and documentation files but no changes have been committed after the initial addition to the repo. | D40: A git repository has been set up containing project, code and documentation files have been added to the repository. A very limited number of commits have been made OR the commit messages are not meaningful. | E40: A git repository has been set up containing project, documentation and code files. There is evidence that a regular commits have taken place with meaningful commit messages as the code has been developed and the documentation files have been updated.
...

Sheet Marks
A1: Code compilation | B1: =Marking!U6 -> 0
A2: Shape data | B2: =Marking!U7 -> 0
A3: Grid creation | B3: =Marking!U8 -> 0
A4: Drawing shapes | B4: =Marking!U9 -> 0
A5: Tic tac toe | B5: =Marking!U10 -> 0
A6: Naming | B6: =Marking!U11 -> 0
A7: Code structure | B7: =Marking!U12 -> 0
A8: Error trapping | B8: =Marking!U13 -> 0
A9: Comments | B9: =Marking!U14 -> 0
A10: Software description | B10: =Marking!U18 -> 0
A11: Files used | B11: =Marking!U19 -> 0
A12: Data items | B12: =Marking!U20 -> 0
A13: Functions | B13: =Marking!U21 -> 0
A14: Testing | B14: =Marking!U22 -> 0
A15: Flowchart 1 | B15: =Marking!U26 -> 0
A16: Flowchart 2 | B16: =Marking!U27 -> 0
A17: Version control | B17: =Marking!U31 -> 0
A18: Robot testing | B18: =Marking!U35 -> 0
B19: =SUM(B1:B18) -> 0
